Workbook

Sheet Setup
A1: Joule Observer: calibration workbook
A2: Compare device display and website against the oscilloscope, then against theory. Team 34, ELECTENG 209.
A4: HOW TO USE
A5: 1. Yellow cells with blue text are inputs. Grey cells are formulas, do not overwrite them.
A6: 2. Set the load, then fill one row per test on 'Calibration Log'. Row 7 is an EXAMPLE: overwrite it.
A7: 3. Scope: Vrms of the source, Vrms across the shunt (mV), and the V-to-I time delay (us, positive = current lags).
A8: 4. Display and website columns: type what you read. Website shows V (2 dp), I (mA), P in W (2 dp). It has no energy field.
A9: 5. 'Summary' gives average and worst-case error per comparison and recommended new scale constants for calcs.h.
A10: 6. 'Energy' is a separate timed test (display energy is whole mWh, so run long enough).
A12: Measurement constants
A13: Item | B13: Value | C13: Unit | D13: Source / note
A14: Shunt resistance | B14: 0.5 | C14: ohm | D14: analogue/MASTER_SCHEMATIC_EE209.asc, 0.5 ohm shunt (calcs.h). Measure the real one with a meter and overwrite.
A15: Nominal frequency | B15: 500 | C15: Hz | D15: README spec: 14 Vrms, 500 Hz
A16: Accuracy spec | B16: 5 | C16: % of full scale | D16: README spec table: +/-5% of full scale
A17: Full scale Vrms | B17: 15.4 | C17: V | D17: ASSUMPTION: 14 V +10% (README source tolerance). Change if the team defines it differently.
A18: Full scale Irms | B18: 595 | C18: mA | D18: ASSUMPTION: 7.5 VA / 12.6 V (largest load at lowest source voltage).
A19: Full scale power | B19: 7500 | C19: mW | D19: ASSUMPTION: 7.5 VA upper load limit, rounded.
A20: Display vs website tolerance, V | B20: 0.01 | C20: V | D20: Website shows 2 dp, so 0.01 V is rounding only.
A21: Display vs website tolerance, I | B21: 1 | C21: mA | D21: Website shows whole mA.
A22: Display vs website tolerance, P | B22: 10 | C22: mW | D22: Website shows W to 2 dp, so 10 mW is rounding only.
A24: Firmware constants (copy from calcs.h / what is flashed)
A25: Constant | B25: Value | C25: Unit | D25: Meaning
A26: ADC_OFFSET_COUNTS | B26: 422 | C26: counts | D26: Bias level subtracted from each sample (2.0625 V / 5 V x 1024)
A27: V_MV_PER_COUNT_X100 | B27: 10926 | C27: x100 mV/count | D27: 109.26 mV of source voltage per ADC count
A28: I_MA_PER_COUNT_X1000 | B28: 3877 | C28: x1000 mA/count | D28: 3.877 mA of load current per ADC count
A29: P_MW_PER_COUNT2_X10000 | B29: 4236 | C29: x10000 mW/count^2 | D29: 0.4236 mW per count x count
A31: ADC and front-end check
A32: Item | B32: Value | C32: Unit | D32: Source / note
A33: Measured AVCC (ADC reference) | B33: 5 | C33: V | D33: Measure on the board with a meter. 5.000 is the nominal placeholder.
A34: Measured bias node (VREF) at ADC pin, no signal | B34: 2.0625 | C34: V | D34: Measure at PC0/PC1 with the source off. 2.0625 is the LTspice value, so overwrite it.
A35: Voltage channel gain | B35: 0.04469 | C35: V/V | D35: From calcs.h comment (divider x difference amp). Check against the LTspice model.
A36: Current channel gain | B36: 1.2593 | C36: mV per mA | D36: From calcs.h comment (0.5 ohm x 2.5185).
A37: ADC step (1 LSB) | B37: =B33/1024*1000 -> 4.8828125 | C37: mV | D37: AVCC / 1024
A38: Bias level in counts (measured) | B38: =B34/B33*1024 -> 422.4 | C38: counts | D38: Compare with ADC_OFFSET_COUNTS
A39: Recommended ADC_OFFSET_COUNTS | B39: =ROUND(B38,0) -> 422 | C39: counts | D39: Use this if it differs from the flashed value
A40: Theoretical voltage scale | B40: =B37/B35 -> 109.25962 | C40: mV/count | D40: LSB / V gain
A41: Theoretical current scale | B41: =B37/B36 -> 3.8774021 | C41: mA/count | D41: LSB / I gain
A42: Theoretical power scale | B42: =B40*B41/1000 -> 0.42364349 | C42: mW/count^2 | D42: mV x mA / 1000
A43: Firmware voltage scale | B43: =B27/100 -> 109.26 | C43: mV/count
A44: Firmware current scale | B44: =B28/1000 -> 3.877 | C44: mA/count
...

Sheet Calibration Log
A1: Calibration log: display / website vs oscilloscope vs theory
A2: One row per test. Errors are (measured - reference) / reference. Pass/fail is on % of full scale (Setup B16). Row 7 is an example.
A4: THEORY INPUTS | I4: OSCILLOSCOPE | N4: DEVICE DISPLAY | Q4: WEBSITE | T4: THEORY (calculated) | W4: SCOPE (calculated) | AA4: ERROR vs SCOPE and THEORY (%) | AP4: CHECKS | AR4: CORRECTION RATIOS
A6: Test # | B6: Load setting / notes | C6: DC Input | D6: Source Vrms (V) | E6: measurement across load | F6: Resistor value | G6: Load S (VA) | H6: Nominal PF | I6: Scope Vrms (V) | J6: Scope shunt Vrms (mV) | K6: V-I SCOPE-PHASE | L6: Scope V-I delay (us) | M6: Scope freq (Hz) | N6: Display Vrms (V) | O6: Display Irms (mA) | P6: Display P (mW) | Q6: Website Vrms (V) | R6: Website Irms (mA) | S6: Website P (W) | T6: Theory Vrms (V) | U6: Theory Irms (mA) | V6: Theory P (mW) | W6: Scope Irms (mA) | X6: Scope phase (deg) | Y6: Scope PF | Z6: Scope P (mW) | AA6: Disp vs Scope: V | AB6: Disp vs Scope: I | AC6: Disp vs Scope: P | AD6: Disp vs Theory: V | AE6: Disp vs Theory: I | AF6: Disp vs Theory: P | AG6: Web vs Scope: V | AH6: Web vs Scope: I | AI6: Web vs Scope: P | AJ6: Web vs Theory: V | AK6: Web vs Theory: I | AL6: Web vs Theory: P | AM6: Scope vs Theory: V | AN6: Scope vs Theory: I | AO6: Scope vs Theory: P | AP6: Display = Website? | AQ6: Display vs Scope (% FS spec) | AR6: Ratio Scope/Disp: V | AS6: Ratio Scope/Disp: I | AT6: Ratio Scope/Disp: P
A7: 1 | B7: EXAMPLE: 5 VA, PF 0.8. Overwrite | D7: 14 | G7: 5 | H7: 0.8 | I7: 14.02 | J7: 178.6 | M7: 500 | N7: 14.06 | O7: 351 | P7: 3950 | Q7: 14.06 | R7: 351 | S7: 3.95 | T7: =IF(D7="","",D7) -> 14 | U7: =IF(OR(D7="",G7="",D7=0),"",G7/D7*1000) -> 357.14286 | V7: =IF(OR(G7="",H7=""),"",G7*H7*1000) -> 4000 | W7: =IF(J7="","",J7/Setup!$B$14) -> 357.2 | X7: =IF(OR(L7="",M7=""),"",360*M7*L7/1000000) | Y7: =IF(X7="","",COS(RADIANS(X7))) | Z7: =IF(OR(I7="",W7="",Y7=""),"",I7*W7*Y7) | AA7: =IF(OR(N7="",I7=""),"",IF(I7=0,"",(N7-I7)/I7)) -> 0.002853067 | AB7: =IF(OR(O7="",W7=""),"",IF(W7=0,"",(O7-W7)/W7)) -> -0.017357223 | AC7: =IF(OR(P7="",Z7=""),"",IF(Z7=0,"",(P7-Z7)/Z7)) | AD7: =IF(OR(N7="",T7=""),"",IF(T7=0,"",(N7-T7)/T7)) -> 0.0042857143 | AE7: =IF(OR(O7="",U7=""),"",IF(U7=0,"",(O7-U7)/U7)) -> -0.0172 | AF7: =IF(OR(P7="",V7=""),"",IF(V7=0,"",(P7-V7)/V7)) -> -0.0125 | AG7: =IF(OR(Q7="",I7=""),"",IF(I7=0,"",(Q7-I7)/I7)) -> 0.002853067 | AH7: =IF(OR(R7="",W7=""),"",IF(W7=0,"",(R7-W7)/W7)) -> -0.017357223 | AI7: =IF(OR(S7="",Z7=""),"",IF(Z7=0,"",(S7*1000-Z7)/Z7)) | AJ7: =IF(OR(Q7="",T7=""),"",IF(T7=0,"",(Q7-T7)/T7)) -> 0.0042857143 | AK7: =IF(OR(R7="",U7=""),"",IF(U7=0,"",(R7-U7)/U7)) -> -0.0172 | AL7: =IF(OR(S7="",V7=""),"",IF(V7=0,"",(S7*1000-V7)/V7)) -> -0.0125 | AM7: =IF(OR(I7="",T7=""),"",IF(T7=0,"",(I7-T7)/T7)) -> 0.0014285714 | AN7: =IF(OR(W7="",U7=""),"",IF(U7=0,"",(W7-U7)/U7)) -> 0.00016 | AO7: =IF(OR(Z7="",V7=""),"",IF(V7=0,"",(Z7-V7)/V7)) | AP7: =IF(OR(N7="",O7="",P7="",Q7="",R7="",S7=""),"",IF(AND(ABS(N7-Q7)<=Setup!$B$20,ABS(O7-R7)<=Setup!$B$21,ABS(P7-S7*1000)<=Setup!$B$22),"OK","CHECK")) -> OK | AQ7: =IF(OR(N7="",O7="",P7="",I7="",W7="",Z7=""),"",IF(AND(ABS(N7-I7)/Setup!$B$17<=Setup!$B$16/100,ABS(O7-W7)/Setup!$B$18<=Setup!$B$16/100,ABS(P7-Z7)/Setup!$B$19<=Setup!$B$16/100),"PASS","FAIL")) | AR7: =IF(OR(I7="",N7="",N7=0),"",I7/N7) -> 0.99715505 | AS7: =IF(OR(W7="",O7="",O7=0),"",W7/O7) -> 1.0176638 | AT7: =IF(OR(Z7="",P7="",P7=0),"",Z7/P7)
A8: 2 | C8: 20V | D8: 12.46 | E8: 12.33 | G8: 7.5 | I8: 12.477 | J8: 244.6 | K8: 36.64 | L8: =(0.002)*(K8/360)*1000000 -> 203.55556 | M8: 500 | N8: 12.7 | O8: 490 | P8: 5.32 | Q8: 12.66 | R8: 491 | S8: 5.48 | T8: =IF(D8="","",D8) -> 12.46 | U8: =IF(OR(D8="",G8="",D8=0),"",G8/D8*1000) -> 601.92616 | V8: =IF(OR(G8="",H8=""),"",G8*H8*1000) | W8: =IF(J8="","",J8/Setup!$B$14) -> 489.2 | X8: =IF(OR(L8="",M8=""),"",360*M8*L8/1000000) -> 36.64 | Y8: =IF(X8="","",COS(RADIANS(X8))) -> 0.80240104 | Z8: =IF(OR(I8="",W8="",Y8=""),"",I8*W8*Y8) -> 4897.654 | AA8: =IF(OR(N8="",I8=""),"",IF(I8=0,"",(N8-I8)/I8)) -> 0.017872886 | AB8: =IF(OR(O8="",W8=""),"",IF(W8=0,"",(O8-W8)/W8)) -> 0.001635323 | AC8: =IF(OR(P8="",Z8=""),"",IF(Z8=0,"",(P8-Z8)/Z8)) -> -0.99891377 | AD8: =IF(OR(N8="",T8=""),"",IF(T8=0,"",(N8-T8)/T8)) -> 0.019261637 | AE8: =IF(OR(O8="",U8=""),"",IF(U8=0,"",(O8-U8)/U8)) -> -0.18594667 | AF8: =IF(OR(P8="",V8=""),"",IF(V8=0,"",(P8-V8)/V8)) | AG8: =IF(OR(Q8="",I8=""),"",IF(I8=0,"",(Q8-I8)/I8)) -> 0.014666987 | AH8: =IF(OR(R8="",W8=""),"",IF(W8=0,"",(R8-W8)/W8)) -> 0.0036794767 | AI8: =IF(OR(S8="",Z8=""),"",IF(Z8=0,"",(S8*1000-Z8)/Z8)) -> 0.11890304 | AJ8: =IF(OR(Q8="",T8=""),"",IF(T8=0,"",(Q8-T8)/T8)) -> 0.016051364 | AK8: =IF(OR(R8="",U8=""),"",IF(U8=0,"",(R8-U8)/U8)) -> -0.18428533 | AL8: =IF(OR(S8="",V8=""),"",IF(V8=0,"",(S8*1000-V8)/V8)) | AM8: =IF(OR(I8="",T8=""),"",IF(T8=0,"",(I8-T8)/T8)) -> 0.001364366 | AN8: =IF(OR(W8="",U8=""),"",IF(U8=0,"",(W8-U8)/U8)) -> -0.18727573 | AO8: =IF(OR(Z8="",V8=""),"",IF(V8=0,"",(Z8-V8)/V8)) | AP8: =IF(OR(N8="",O8="",P8="",Q8="",R8="",S8=""),"",IF(AND(ABS(N8-Q8)<=Setup!$B$20,ABS(O8-R8)<=Setup!$B$21,ABS(P8-S8*1000)<=Setup!$B$22),"OK","CHECK")) -> CHECK | AQ8: =IF(OR(N8="",O8="",P8="",I8="",W8="",Z8=""),"",IF(AND(ABS(N8-I8)/Setup!$B$17<=Setup!$B$16/100,ABS(O8-W8)/Setup!$B$18<=Setup!$B$16/100,ABS(P8-Z8)/Setup!$B$19<=Setup!$B$16/100),"PASS","FAIL")) -> FAIL | AR8: =IF(OR(I8="",N8="",N8=0),"",I8/N8) -> 0.98244094 | AS8: =IF(OR(W8="",O8="",O8=0),"",W8/O8) -> 0.99836735 | AT8: =IF(OR(Z8="",P8="",P8=0),"",Z8/P8) -> 920.61166
A9: 3 | C9: 21V | D9: 12.66 | E9: 12.437 | G9: 7.5 | I9: 12.679 | J9: 497.7 | M9: 501.6 | N9: 12.8 | Q9: 12.82 | T9: =IF(D9="","",D9) -> 12.66 | U9: =IF(OR(D9="",G9="",D9=0),"",G9/D9*1000) -> 592.41706 | V9: =IF(OR(G9="",H9=""),"",G9*H9*1000) | W9: =IF(J9="","",J9/Setup!$B$14) -> 995.4 | X9: =IF(OR(L9="",M9=""),"",360*M9*L9/1000000) | Y9: =IF(X9="","",COS(RADIANS(X9))) | Z9: =IF(OR(I9="",W9="",Y9=""),"",I9*W9*Y9) | AA9: =IF(OR(N9="",I9=""),"",IF(I9=0,"",(N9-I9)/I9)) -> 0.0095433394 | AB9: =IF(OR(O9="",W9=""),"",IF(W9=0,"",(O9-W9)/W9)) | AC9: =IF(OR(P9="",Z9=""),"",IF(Z9=0,"",(P9-Z9)/Z9)) | AD9: =IF(OR(N9="",T9=""),"",IF(T9=0,"",(N9-T9)/T9)) -> 0.011058452 | AE9: =IF(OR(O9="",U9=""),"",IF(U9=0,"",(O9-U9)/U9)) | AF9: =IF(OR(P9="",V9=""),"",IF(V9=0,"",(P9-V9)/V9)) | AG9: =IF(OR(Q9="",I9=""),"",IF(I9=0,"",(Q9-I9)/I9)) -> 0.011120751 | AH9: =IF(OR(R9="",W9=""),"",IF(W9=0,"",(R9-W9)/W9)) | AI9: =IF(OR(S9="",Z9=""),"",IF(Z9=0,"",(S9*1000-Z9)/Z9)) | AJ9: =IF(OR(Q9="",T9=""),"",IF(T9=0,"",(Q9-T9)/T9)) -> 0.012638231 | AK9: =IF(OR(R9="",U9=""),"",IF(U9=0,"",(R9-U9)/U9)) | AL9: =IF(OR(S9="",V9=""),"",IF(V9=0,"",(S9*1000-V9)/V9)) | AM9: =IF(OR(I9="",T9=""),"",IF(T9=0,"",(I9-T9)/T9)) -> 0.0015007899 | AN9: =IF(OR(W9="",U9=""),"",IF(U9=0,"",(W9-U9)/U9)) -> 0.6802352 | AO9: =IF(OR(Z9="",V9=""),"",IF(V9=0,"",(Z9-V9)/V9)) | AP9: =IF(OR(N9="",O9="",P9="",Q9="",R9="",S9=""),"",IF(AND(ABS(N9-Q9)<=Setup!$B$20,ABS(O9-R9)<=Setup!$B$21,ABS(P9-S9*1000)<=Setup!$B$22),"OK","CHECK")) | AQ9: =IF(OR(N9="",O9="",P9="",I9="",W9="",Z9=""),"",IF(AND(ABS(N9-I9)/Setup!$B$17<=Setup!$B$16/100,ABS(O9-W9)/Setup!$B$18<=Setup!$B$16/100,ABS(P9-Z9)/Setup!$B$19<=Setup!$B$16/100),"PASS","FAIL")) | AR9: =IF(OR(I9="",N9="",N9=0),"",I9/N9) -> 0.99054687 | AS9: =IF(OR(W9="",O9="",O9=0),"",W9/O9) | AT9: =IF(OR(Z9="",P9="",P9=0),"",Z9/P9)
A10: 4 | C10: 22V | D10: 12.78 | E10: 12.58 | G10: 7.5 | I10: 12.849 | J10: 506.3 | M10: 501 | N10: 12.9 | Q10: 12.95 | T10: =IF(D10="","",D10) -> 12.78 | U10: =IF(OR(D10="",G10="",D10=0),"",G10/D10*1000) -> 586.85446 | V10: =IF(OR(G10="",H10=""),"",G10*H10*1000) | W10: =IF(J10="","",J10/Setup!$B$14) -> 1012.6 | X10: =IF(OR(L10="",M10=""),"",360*M10*L10/1000000) | Y10: =IF(X10="","",COS(RADIANS(X10))) | Z10: =IF(OR(I10="",W10="",Y10=""),"",I10*W10*Y10) | AA10: =IF(OR(N10="",I10=""),"",IF(I10=0,"",(N10-I10)/I10)) -> 0.0039691805 | AB10: =IF(OR(O10="",W10=""),"",IF(W10=0,"",(O10-W10)/W10)) | AC10: =IF(OR(P10="",Z10=""),"",IF(Z10=0,"",(P10-Z10)/Z10)) | AD10: =IF(OR(N10="",T10=""),"",IF(T10=0,"",(N10-T10)/T10)) -> 0.0093896714 | AE10: =IF(OR(O10="",U10=""),"",IF(U10=0,"",(O10-U10)/U10)) | AF10: =IF(OR(P10="",V10=""),"",IF(V10=0,"",(P10-V10)/V10)) | AG10: =IF(OR(Q10="",I10=""),"",IF(I10=0,"",(Q10-I10)/I10)) -> 0.0078605339 | AH10: =IF(OR(R10="",W10=""),"",IF(W10=0,"",(R10-W10)/W10)) | AI10: =IF(OR(S10="",Z10=""),"",IF(Z10=0,"",(S10*1000-Z10)/Z10)) | AJ10: =IF(OR(Q10="",T10=""),"",IF(T10=0,"",(Q10-T10)/T10)) -> 0.013302034 | AK10: =IF(OR(R10="",U10=""),"",IF(U10=0,"",(R10-U10)/U10)) | AL10: =IF(OR(S10="",V10=""),"",IF(V10=0,"",(S10*1000-V10)/V10)) | AM10: =IF(OR(I10="",T10=""),"",IF(T10=0,"",(I10-T10)/T10)) -> 0.005399061 | AN10: =IF(OR(W10="",U10=""),"",IF(U10=0,"",(W10-U10)/U10)) -> 0.7254704 | AO10: =IF(OR(Z10="",V10=""),"",IF(V10=0,"",(Z10-V10)/V10)) | AP10: =IF(OR(N10="",O10="",P10="",Q10="",R10="",S10=""),"",IF(AND(ABS(N10-Q10)<=Setup!$B$20,ABS(O10-R10)<=Setup!$B$21,ABS(P10-S10*1000)<=Setup!$B$22),"OK","CHECK")) | AQ10: =IF(OR(N10="",O10="",P10="",I10="",W10="",Z10=""),"",IF(AND(ABS(N10-I10)/Setup!$B$17<=Setup!$B$16/100,ABS(O10-W10)/Setup!$B$18<=Setup!$B$16/100,ABS(P10-Z10)/Setup!$B$19<=Setup!$B$16/100),"PASS","FAIL")) | AR10: =IF(OR(I10="",N10="",N10=0),"",I10/N10) -> 0.99604651 | AS10: =IF(OR(W10="",O10="",O10=0),"",W10/O10) | AT10: =IF(OR(Z10="",P10="",P10=0),"",Z10/P10)
A11: 5 | C11: 23V | D11: 12.903 | E11: 12.68 | G11: 7.5 | I11: 12.95 | J11: 518.7 | M11: 501 | N11: 13.1 | Q11: 13.09 | T11: =IF(D11="","",D11) -> 12.903 | U11: =IF(OR(D11="",G11="",D11=0),"",G11/D11*1000) -> 581.26017 | V11: =IF(OR(G11="",H11=""),"",G11*H11*1000) | W11: =IF(J11="","",J11/Setup!$B$14) -> 1037.4 | X11: =IF(OR(L11="",M11=""),"",360*M11*L11/1000000) | Y11: =IF(X11="","",COS(RADIANS(X11))) | Z11: =IF(OR(I11="",W11="",Y11=""),"",I11*W11*Y11) | AA11: =IF(OR(N11="",I11=""),"",IF(I11=0,"",(N11-I11)/I11)) -> 0.011583012 | AB11: =IF(OR(O11="",W11=""),"",IF(W11=0,"",(O11-W11)/W11)) | AC11: =IF(OR(P11="",Z11=""),"",IF(Z11=0,"",(P11-Z11)/Z11)) | AD11: =IF(OR(N11="",T11=""),"",IF(T11=0,"",(N11-T11)/T11)) -> 0.015267767 | AE11: =IF(OR(O11="",U11=""),"",IF(U11=0,"",(O11-U11)/U11)) | AF11: =IF(OR(P11="",V11=""),"",IF(V11=0,"",(P11-V11)/V11)) | AG11: =IF(OR(Q11="",I11=""),"",IF(I11=0,"",(Q11-I11)/I11)) -> 0.010810811 | AH11: =IF(OR(R11="",W11=""),"",IF(W11=0,"",(R11-W11)/W11)) | AI11: =IF(OR(S11="",Z11=""),"",IF(Z11=0,"",(S11*1000-Z11)/Z11)) | AJ11: =IF(OR(Q11="",T11=""),"",IF(T11=0,"",(Q11-T11)/T11)) -> 0.014492754 | AK11: =IF(OR(R11="",U11=""),"",IF(U11=0,"",(R11-U11)/U11)) | AL11: =IF(OR(S11="",V11=""),"",IF(V11=0,"",(S11*1000-V11)/V11)) | AM11: =IF(OR(I11="",T11=""),"",IF(T11=0,"",(I11-T11)/T11)) -> 0.0036425637 | AN11: =IF(OR(W11="",U11=""),"",IF(U11=0,"",(W11-U11)/U11)) -> 0.78474296 | AO11: =IF(OR(Z11="",V11=""),"",IF(V11=0,"",(Z11-V11)/V11)) | AP11: =IF(OR(N11="",O11="",P11="",Q11="",R11="",S11=""),"",IF(AND(ABS(N11-Q11)<=Setup!$B$20,ABS(O11-R11)<=Setup!$B$21,ABS(P11-S11*1000)<=Setup!$B$22),"OK","CHECK")) | AQ11: =IF(OR(N11="",O11="",P11="",I11="",W11="",Z11=""),"",IF(AND(ABS(N11-I11)/Setup!$B$17<=Setup!$B$16/100,ABS(O11-W11)/Setup!$B$18<=Setup!$B$16/100,ABS(P11-Z11)/Setup!$B$19<=Setup!$B$16/100),"PASS","FAIL")) | AR11: =IF(OR(I11="",N11="",N11=0),"",I11/N11) -> 0.98854962 | AS11: =IF(OR(W11="",O11="",O11=0),"",W11/O11) | AT11: =IF(OR(Z11="",P11="",P11=0),"",Z11/P11)
A12: 6 | C12: 26V | G12: 7.5
A13: 7 | C13: 29V | G13: 7.5
A14: 8 | C14: 32V | G14: 7.5
A15: 9 | G15: 7.5
A16: 10 | T16: =IF(D16="","",D16) | U16: =IF(OR(D16="",G16="",D16=0),"",G16/D16*1000) | V16: =IF(OR(G16="",H16=""),"",G16*H16*1000) | W16: =IF(J16="","",J16/Setup!$B$14) | X16: =IF(OR(L16="",M16=""),"",360*M16*L16/1000000) | Y16: =IF(X16="","",COS(RADIANS(X16))) | Z16: =IF(OR(I16="",W16="",Y16=""),"",I16*W16*Y16) | AA16: =IF(OR(N16="",I16=""),"",IF(I16=0,"",(N16-I16)/I16)) | AB16: =IF(OR(O16="",W16=""),"",IF(W16=0,"",(O16-W16)/W16)) | AC16: =IF(OR(P16="",Z16=""),"",IF(Z16=0,"",(P16-Z16)/Z16)) | AD16: =IF(OR(N16="",T16=""),"",IF(T16=0,"",(N16-T16)/T16)) | AE16: =IF(OR(O16="",U16=""),"",IF(U16=0,"",(O16-U16)/U16)) | AF16: =IF(OR(P16="",V16=""),"",IF(V16=0,"",(P16-V16)/V16)) | AG16: =IF(OR(Q16="",I16=""),"",IF(I16=0,"",(Q16-I16)/I16)) | AH16: =IF(OR(R16="",W16=""),"",IF(W16=0,"",(R16-W16)/W16)) | AI16: =IF(OR(S16="",Z16=""),"",IF(Z16=0,"",(S16*1000-Z16)/Z16)) | AJ16: =IF(OR(Q16="",T16=""),"",IF(T16=0,"",(Q16-T16)/T16)) | AK16: =IF(OR(R16="",U16=""),"",IF(U16=0,"",(R16-U16)/U16)) | AL16: =IF(OR(S16="",V16=""),"",IF(V16=0,"",(S16*1000-V16)/V16)) | AM16: =IF(OR(I16="",T16=""),"",IF(T16=0,"",(I16-T16)/T16)) | AN16: =IF(OR(W16="",U16=""),"",IF(U16=0,"",(W16-U16)/U16)) | AO16: =IF(OR(Z16="",V16=""),"",IF(V16=0,"",(Z16-V16)/V16)) | AP16: =IF(OR(N16="",O16="",P16="",Q16="",R16="",S16=""),"",IF(AND(ABS(N16-Q16)<=Setup!$B$20,ABS(O16-R16)<=Setup!$B$21,ABS(P16-S16*1000)<=Setup!$B$22),"OK","CHECK")) | AQ16: =IF(OR(N16="",O16="",P16="",I16="",W16="",Z16=""),"",IF(AND(ABS(N16-I16)/Setup!$B$17<=Setup!$B$16/100,ABS(O16-W16)/Setup!$B$18<=Setup!$B$16/100,ABS(P16-Z16)/Setup!$B$19<=Setup!$B$16/100),"PASS","FAIL")) | AR16: =IF(OR(I16="",N16="",N16=0),"",I16/N16) | AS16: =IF(OR(W16="",O16="",O16=0),"",W16/O16) | AT16: =IF(OR(Z16="",P16="",P16=0),"",Z16/P16)
A17: 11 | C17: 20V | D17: 12.959 | E17: 12.898 | G17: 2.5 | I17: 13 | J17: 66.98 | M17: 501 | N17: 13.1 | Q17: 13.14 | T17: =IF(D17="","",D17) -> 12.959 | U17: =IF(OR(D17="",G17="",D17=0),"",G17/D17*1000) -> 192.91612 | V17: =IF(OR(G17="",H17=""),"",G17*H17*1000) | W17: =IF(J17="","",J17/Setup!$B$14) -> 133.96 | X17: =IF(OR(L17="",M17=""),"",360*M17*L17/1000000) | Y17: =IF(X17="","",COS(RADIANS(X17))) | Z17: =IF(OR(I17="",W17="",Y17=""),"",I17*W17*Y17) | AA17: =IF(OR(N17="",I17=""),"",IF(I17=0,"",(N17-I17)/I17)) -> 0.0076923077 | AB17: =IF(OR(O17="",W17=""),"",IF(W17=0,"",(O17-W17)/W17)) | AC17: =IF(OR(P17="",Z17=""),"",IF(Z17=0,"",(P17-Z17)/Z17)) | AD17: =IF(OR(N17="",T17=""),"",IF(T17=0,"",(N17-T17)/T17)) -> 0.010880469 | AE17: =IF(OR(O17="",U17=""),"",IF(U17=0,"",(O17-U17)/U17)) | AF17: =IF(OR(P17="",V17=""),"",IF(V17=0,"",(P17-V17)/V17)) | AG17: =IF(OR(Q17="",I17=""),"",IF(I17=0,"",(Q17-I17)/I17)) -> 0.010769231 | AH17: =IF(OR(R17="",W17=""),"",IF(W17=0,"",(R17-W17)/W17)) | AI17: =IF(OR(S17="",Z17=""),"",IF(Z17=0,"",(S17*1000-Z17)/Z17)) | AJ17: =IF(OR(Q17="",T17=""),"",IF(T17=0,"",(Q17-T17)/T17)) -> 0.013967127 | AK17: =IF(OR(R17="",U17=""),"",IF(U17=0,"",(R17-U17)/U17)) | AL17: =IF(OR(S17="",V17=""),"",IF(V17=0,"",(S17*1000-V17)/V17)) | AM17: =IF(OR(I17="",T17=""),"",IF(T17=0,"",(I17-T17)/T17)) -> 0.0031638244 | AN17: =IF(OR(W17="",U17=""),"",IF(U17=0,"",(W17-U17)/U17)) -> -0.30560494 | AO17: =IF(OR(Z17="",V17=""),"",IF(V17=0,"",(Z17-V17)/V17)) | AP17: =IF(OR(N17="",O17="",P17="",Q17="",R17="",S17=""),"",IF(AND(ABS(N17-Q17)<=Setup!$B$20,ABS(O17-R17)<=Setup!$B$21,ABS(P17-S17*1000)<=Setup!$B$22),"OK","CHECK")) | AQ17: =IF(OR(N17="",O17="",P17="",I17="",W17="",Z17=""),"",IF(AND(ABS(N17-I17)/Setup!$B$17<=Setup!$B$16/100,ABS(O17-W17)/Setup!$B$18<=Setup!$B$16/100,ABS(P17-Z17)/Setup!$B$19<=Setup!$B$16/100),"PASS","FAIL")) | AR17: =IF(OR(I17="",N17="",N17=0),"",I17/N17) -> 0.99236641 | AS17: =IF(OR(W17="",O17="",O17=0),"",W17/O17) | AT17: =IF(OR(Z17="",P17="",P17=0),"",Z17/P17)
A18: 12 | C18: 21V | D18: 13.108 | E18: 13.045 | G18: 2.5 | I18: 13.15 | J18: 67.75 | M18: 501 | N18: 13.3 | Q18: 13.29 | T18: =IF(D18="","",D18) -> 13.108 | U18: =IF(OR(D18="",G18="",D18=0),"",G18/D18*1000) -> 190.72322 | V18: =IF(OR(G18="",H18=""),"",G18*H18*1000) | W18: =IF(J18="","",J18/Setup!$B$14) -> 135.5 | X18: =IF(OR(L18="",M18=""),"",360*M18*L18/1000000) | Y18: =IF(X18="","",COS(RADIANS(X18))) | Z18: =IF(OR(I18="",W18="",Y18=""),"",I18*W18*Y18) | AA18: =IF(OR(N18="",I18=""),"",IF(I18=0,"",(N18-I18)/I18)) -> 0.011406844 | AB18: =IF(OR(O18="",W18=""),"",IF(W18=0,"",(O18-W18)/W18)) | AC18: =IF(OR(P18="",Z18=""),"",IF(Z18=0,"",(P18-Z18)/Z18)) | AD18: =IF(OR(N18="",T18=""),"",IF(T18=0,"",(N18-T18)/T18)) -> 0.014647543 | AE18: =IF(OR(O18="",U18=""),"",IF(U18=0,"",(O18-U18)/U18)) | AF18: =IF(OR(P18="",V18=""),"",IF(V18=0,"",(P18-V18)/V18)) | AG18: =IF(OR(Q18="",I18=""),"",IF(I18=0,"",(Q18-I18)/I18)) -> 0.010646388 | AH18: =IF(OR(R18="",W18=""),"",IF(W18=0,"",(R18-W18)/W18)) | AI18: =IF(OR(S18="",Z18=""),"",IF(Z18=0,"",(S18*1000-Z18)/Z18)) | AJ18: =IF(OR(Q18="",T18=""),"",IF(T18=0,"",(Q18-T18)/T18)) -> 0.013884651 | AK18: =IF(OR(R18="",U18=""),"",IF(U18=0,"",(R18-U18)/U18)) | AL18: =IF(OR(S18="",V18=""),"",IF(V18=0,"",(S18*1000-V18)/V18)) | AM18: =IF(OR(I18="",T18=""),"",IF(T18=0,"",(I18-T18)/T18)) -> 0.0032041501 | AN18: =IF(OR(W18="",U18=""),"",IF(U18=0,"",(W18-U18)/U18)) -> -0.2895464 | AO18: =IF(OR(Z18="",V18=""),"",IF(V18=0,"",(Z18-V18)/V18)) | AP18: =IF(OR(N18="",O18="",P18="",Q18="",R18="",S18=""),"",IF(AND(ABS(N18-Q18)<=Setup!$B$20,ABS(O18-R18)<=Setup!$B$21,ABS(P18-S18*1000)<=Setup!$B$22),"OK","CHECK")) | AQ18: =IF(OR(N18="",O18="",P18="",I18="",W18="",Z18=""),"",IF(AND(ABS(N18-I18)/Setup!$B$17<=Setup!$B$16/100,ABS(O18-W18)/Setup!$B$18<=Setup!$B$16/100,ABS(P18-Z18)/Setup!$B$19<=Setup!$B$16/100),"PASS","FAIL")) | AR18: =IF(OR(I18="",N18="",N18=0),"",I18/N18) -> 0.9887218 | AS18: =IF(OR(W18="",O18="",O18=0),"",W18/O18) | AT18: =IF(OR(Z18="",P18="",P18=0),"",Z18/P18)
A19: 13 | C19: 22V | D19: 13.225 | E19: 13.156 | G19: 2.5 | I19: 13.27 | J19: 68.32 | M19: 501 | N19: 13.4 | Q19: 13.41 | T19: =IF(D19="","",D19) -> 13.225 | U19: =IF(OR(D19="",G19="",D19=0),"",G19/D19*1000) -> 189.03592 | V19: =IF(OR(G19="",H19=""),"",G19*H19*1000) | W19: =IF(J19="","",J19/Setup!$B$14) -> 136.64 | X19: =IF(OR(L19="",M19=""),"",360*M19*L19/1000000) | Y19: =IF(X19="","",COS(RADIANS(X19))) | Z19: =IF(OR(I19="",W19="",Y19=""),"",I19*W19*Y19) | AA19: =IF(OR(N19="",I19=""),"",IF(I19=0,"",(N19-I19)/I19)) -> 0.0097965335 | AB19: =IF(OR(O19="",W19=""),"",IF(W19=0,"",(O19-W19)/W19)) | AC19: =IF(OR(P19="",Z19=""),"",IF(Z19=0,"",(P19-Z19)/Z19)) | AD19: =IF(OR(N19="",T19=""),"",IF(T19=0,"",(N19-T19)/T19)) -> 0.013232514 | AE19: =IF(OR(O19="",U19=""),"",IF(U19=0,"",(O19-U19)/U19)) | AF19: =IF(OR(P19="",V19=""),"",IF(V19=0,"",(P19-V19)/V19)) | AG19: =IF(OR(Q19="",I19=""),"",IF(I19=0,"",(Q19-I19)/I19)) -> 0.010550113 | AH19: =IF(OR(R19="",W19=""),"",IF(W19=0,"",(R19-W19)/W19)) | AI19: =IF(OR(S19="",Z19=""),"",IF(Z19=0,"",(S19*1000-Z19)/Z19)) | AJ19: =IF(OR(Q19="",T19=""),"",IF(T19=0,"",(Q19-T19)/T19)) -> 0.013988658 | AK19: =IF(OR(R19="",U19=""),"",IF(U19=0,"",(R19-U19)/U19)) | AL19: =IF(OR(S19="",V19=""),"",IF(V19=0,"",(S19*1000-V19)/V19)) | AM19: =IF(OR(I19="",T19=""),"",IF(T19=0,"",(I19-T19)/T19)) -> 0.0034026465 | AN19: =IF(OR(W19="",U19=""),"",IF(U19=0,"",(W19-U19)/U19)) -> -0.2771744 | AO19: =IF(OR(Z19="",V19=""),"",IF(V19=0,"",(Z19-V19)/V19)) | AP19: =IF(OR(N19="",O19="",P19="",Q19="",R19="",S19=""),"",IF(AND(ABS(N19-Q19)<=Setup!$B$20,ABS(O19-R19)<=Setup!$B$21,ABS(P19-S19*1000)<=Setup!$B$22),"OK","CHECK")) | AQ19: =IF(OR(N19="",O19="",P19="",I19="",W19="",Z19=""),"",IF(AND(ABS(N19-I19)/Setup!$B$17<=Setup!$B$16/100,ABS(O19-W19)/Setup!$B$18<=Setup!$B$16/100,ABS(P19-Z19)/Setup!$B$19<=Setup!$B$16/100),"PASS","FAIL")) | AR19: =IF(OR(I19="",N19="",N19=0),"",I19/N19) -> 0.99029851 | AS19: =IF(OR(W19="",O19="",O19=0),"",W19/O19) | AT19: =IF(OR(Z19="",P19="",P19=0),"",Z19/P19)
A20: 14 | C20: 23V | D20: 13.332 | E20: 13.269 | G20: 2.5 | I20: 13.35 | J20: 68.82 | M20: 501 | N20: 13.5 | Q20: 13.53 | T20: =IF(D20="","",D20) -> 13.332 | U20: =IF(OR(D20="",G20="",D20=0),"",G20/D20*1000) -> 187.51875 | V20: =IF(OR(G20="",H20=""),"",G20*H20*1000) | W20: =IF(J20="","",J20/Setup!$B$14) -> 137.64 | X20: =IF(OR(L20="",M20=""),"",360*M20*L20/1000000) | Y20: =IF(X20="","",COS(RADIANS(X20))) | Z20: =IF(OR(I20="",W20="",Y20=""),"",I20*W20*Y20) | AA20: =IF(OR(N20="",I20=""),"",IF(I20=0,"",(N20-I20)/I20)) -> 0.011235955 | AB20: =IF(OR(O20="",W20=""),"",IF(W20=0,"",(O20-W20)/W20)) | AC20: =IF(OR(P20="",Z20=""),"",IF(Z20=0,"",(P20-Z20)/Z20)) | AD20: =IF(OR(N20="",T20=""),"",IF(T20=0,"",(N20-T20)/T20)) -> 0.01260126 | AE20: =IF(OR(O20="",U20=""),"",IF(U20=0,"",(O20-U20)/U20)) | AF20: =IF(OR(P20="",V20=""),"",IF(V20=0,"",(P20-V20)/V20)) | AG20: =IF(OR(Q20="",I20=""),"",IF(I20=0,"",(Q20-I20)/I20)) -> 0.013483146 | AH20: =IF(OR(R20="",W20=""),"",IF(W20=0,"",(R20-W20)/W20)) | AI20: =IF(OR(S20="",Z20=""),"",IF(Z20=0,"",(S20*1000-Z20)/Z20)) | AJ20: =IF(OR(Q20="",T20=""),"",IF(T20=0,"",(Q20-T20)/T20)) -> 0.014851485 | AK20: =IF(OR(R20="",U20=""),"",IF(U20=0,"",(R20-U20)/U20)) | AL20: =IF(OR(S20="",V20=""),"",IF(V20=0,"",(S20*1000-V20)/V20)) | AM20: =IF(OR(I20="",T20=""),"",IF(T20=0,"",(I20-T20)/T20)) -> 0.001350135 | AN20: =IF(OR(W20="",U20=""),"",IF(U20=0,"",(W20-U20)/U20)) -> -0.26599341 | AO20: =IF(OR(Z20="",V20=""),"",IF(V20=0,"",(Z20-V20)/V20)) | AP20: =IF(OR(N20="",O20="",P20="",Q20="",R20="",S20=""),"",IF(AND(ABS(N20-Q20)<=Setup!$B$20,ABS(O20-R20)<=Setup!$B$21,ABS(P20-S20*1000)<=Setup!$B$22),"OK","CHECK")) | AQ20: =IF(OR(N20="",O20="",P20="",I20="",W20="",Z20=""),"",IF(AND(ABS(N20-I20)/Setup!$B$17<=Setup!$B$16/100,ABS(O20-W20)/Setup!$B$18<=Setup!$B$16/100,ABS(P20-Z20)/Setup!$B$19<=Setup!$B$16/100),"PASS","FAIL")) | AR20: =IF(OR(I20="",N20="",N20=0),"",I20/N20) -> 0.98888889 | AS20: =IF(OR(W20="",O20="",O20=0),"",W20/O20) | AT20: =IF(OR(Z20="",P20="",P20=0),"",Z20/P20)
A21: 15 | C21: 26V | D21: 13.58 | E21: 13.518 | G21: 2.5 | I21: 13.63 | J21: 70.24 | M21: 501 | N21: 13.8 | Q21: 13.79 | T21: =IF(D21="","",D21) -> 13.58 | U21: =IF(OR(D21="",G21="",D21=0),"",G21/D21*1000) -> 184.09426 | V21: =IF(OR(G21="",H21=""),"",G21*H21*1000) | W21: =IF(J21="","",J21/Setup!$B$14) -> 140.48 | X21: =IF(OR(L21="",M21=""),"",360*M21*L21/1000000) | Y21: =IF(X21="","",COS(RADIANS(X21))) | Z21: =IF(OR(I21="",W21="",Y21=""),"",I21*W21*Y21) | AA21: =IF(OR(N21="",I21=""),"",IF(I21=0,"",(N21-I21)/I21)) -> 0.012472487 | AB21: =IF(OR(O21="",W21=""),"",IF(W21=0,"",(O21-W21)/W21)) | AC21: =IF(OR(P21="",Z21=""),"",IF(Z21=0,"",(P21-Z21)/Z21)) | AD21: =IF(OR(N21="",T21=""),"",IF(T21=0,"",(N21-T21)/T21)) -> 0.016200295 | AE21: =IF(OR(O21="",U21=""),"",IF(U21=0,"",(O21-U21)/U21)) | AF21: =IF(OR(P21="",V21=""),"",IF(V21=0,"",(P21-V21)/V21)) | AG21: =IF(OR(Q21="",I21=""),"",IF(I21=0,"",(Q21-I21)/I21)) -> 0.011738811 | AH21: =IF(OR(R21="",W21=""),"",IF(W21=0,"",(R21-W21)/W21)) | AI21: =IF(OR(S21="",Z21=""),"",IF(Z21=0,"",(S21*1000-Z21)/Z21)) | AJ21: =IF(OR(Q21="",T21=""),"",IF(T21=0,"",(Q21-T21)/T21)) -> 0.015463918 | AK21: =IF(OR(R21="",U21=""),"",IF(U21=0,"",(R21-U21)/U21)) | AL21: =IF(OR(S21="",V21=""),"",IF(V21=0,"",(S21*1000-V21)/V21)) | AM21: =IF(OR(I21="",T21=""),"",IF(T21=0,"",(I21-T21)/T21)) -> 0.0036818851 | AN21: =IF(OR(W21="",U21=""),"",IF(U21=0,"",(W21-U21)/U21)) -> -0.23691264 | AO21: =IF(OR(Z21="",V21=""),"",IF(V21=0,"",(Z21-V21)/V21)) | AP21: =IF(OR(N21="",O21="",P21="",Q21="",R21="",S21=""),"",IF(AND(ABS(N21-Q21)<=Setup!$B$20,ABS(O21-R21)<=Setup!$B$21,ABS(P21-S21*1000)<=Setup!$B$22),"OK","CHECK")) | AQ21: =IF(OR(N21="",O21="",P21="",I21="",W21="",Z21=""),"",IF(AND(ABS(N21-I21)/Setup!$B$17<=Setup!$B$16/100,ABS(O21-W21)/Setup!$B$18<=Setup!$B$16/100,ABS(P21-Z21)/Setup!$B$19<=Setup!$B$16/100),"PASS","FAIL")) | AR21: =IF(OR(I21="",N21="",N21=0),"",I21/N21) -> 0.98768116 | AS21: =IF(OR(W21="",O21="",O21=0),"",W21/O21) | AT21: =IF(OR(Z21="",P21="",P21=0),"",Z21/P21)
A22: 16 | C22: 29V | D22: 13.76 | E22: 13.69 | G22: 2.5 | I22: 13.81 | J22: 71.22 | M22: 502 | N22: 14 | Q22: 13.97 | T22: =IF(D22="","",D22) -> 13.76 | U22: =IF(OR(D22="",G22="",D22=0),"",G22/D22*1000) -> 181.68605 | V22: =IF(OR(G22="",H22=""),"",G22*H22*1000) | W22: =IF(J22="","",J22/Setup!$B$14) -> 142.44 | X22: =IF(OR(L22="",M22=""),"",360*M22*L22/1000000) | Y22: =IF(X22="","",COS(RADIANS(X22))) | Z22: =IF(OR(I22="",W22="",Y22=""),"",I22*W22*Y22) | AA22: =IF(OR(N22="",I22=""),"",IF(I22=0,"",(N22-I22)/I22)) -> 0.013758146 | AB22: =IF(OR(O22="",W22=""),"",IF(W22=0,"",(O22-W22)/W22)) | AC22: =IF(OR(P22="",Z22=""),"",IF(Z22=0,"",(P22-Z22)/Z22)) | AD22: =IF(OR(N22="",T22=""),"",IF(T22=0,"",(N22-T22)/T22)) -> 0.01744186 | AE22: =IF(OR(O22="",U22=""),"",IF(U22=0,"",(O22-U22)/U22)) | AF22: =IF(OR(P22="",V22=""),"",IF(V22=0,"",(P22-V22)/V22)) | AG22: =IF(OR(Q22="",I22=""),"",IF(I22=0,"",(Q22-I22)/I22)) -> 0.011585807 | AH22: =IF(OR(R22="",W22=""),"",IF(W22=0,"",(R22-W22)/W22)) | AI22: =IF(OR(S22="",Z22=""),"",IF(Z22=0,"",(S22*1000-Z22)/Z22)) | AJ22: =IF(OR(Q22="",T22=""),"",IF(T22=0,"",(Q22-T22)/T22)) -> 0.015261628 | AK22: =IF(OR(R22="",U22=""),"",IF(U22=0,"",(R22-U22)/U22)) | AL22: =IF(OR(S22="",V22=""),"",IF(V22=0,"",(S22*1000-V22)/V22)) | AM22: =IF(OR(I22="",T22=""),"",IF(T22=0,"",(I22-T22)/T22)) -> 0.0036337209 | AN22: =IF(OR(W22="",U22=""),"",IF(U22=0,"",(W22-U22)/U22)) -> -0.21601024 | AO22: =IF(OR(Z22="",V22=""),"",IF(V22=0,"",(Z22-V22)/V22)) | AP22: =IF(OR(N22="",O22="",P22="",Q22="",R22="",S22=""),"",IF(AND(ABS(N22-Q22)<=Setup!$B$20,ABS(O22-R22)<=Setup!$B$21,ABS(P22-S22*1000)<=Setup!$B$22),"OK","CHECK")) | AQ22: =IF(OR(N22="",O22="",P22="",I22="",W22="",Z22=""),"",IF(AND(ABS(N22-I22)/Setup!$B$17<=Setup!$B$16/100,ABS(O22-W22)/Setup!$B$18<=Setup!$B$16/100,ABS(P22-Z22)/Setup!$B$19<=Setup!$B$16/100),"PASS","FAIL")) | AR22: =IF(OR(I22="",N22="",N22=0),"",I22/N22) -> 0.98642857 | AS22: =IF(OR(W22="",O22="",O22=0),"",W22/O22) | AT22: =IF(OR(Z22="",P22="",P22=0),"",Z22/P22)
A23: 17 | C23: 32V | D23: 13.877 | E23: 13.82 | G23: 2.5 | I23: 13.93 | J23: 71.79 | M23: 501 | N23: 14.1 | Q23: 14.09 | T23: =IF(D23="","",D23) -> 13.877 | U23: =IF(OR(D23="",G23="",D23=0),"",G23/D23*1000) -> 180.15421 | V23: =IF(OR(G23="",H23=""),"",G23*H23*1000) | W23: =IF(J23="","",J23/Setup!$B$14) -> 143.58 | X23: =IF(OR(L23="",M23=""),"",360*M23*L23/1000000) | Y23: =IF(X23="","",COS(RADIANS(X23))) | Z23: =IF(OR(I23="",W23="",Y23=""),"",I23*W23*Y23) | AA23: =IF(OR(N23="",I23=""),"",IF(I23=0,"",(N23-I23)/I23)) -> 0.012203877 | AB23: =IF(OR(O23="",W23=""),"",IF(W23=0,"",(O23-W23)/W23)) | AC23: =IF(OR(P23="",Z23=""),"",IF(Z23=0,"",(P23-Z23)/Z23)) | AD23: =IF(OR(N23="",T23=""),"",IF(T23=0,"",(N23-T23)/T23)) -> 0.016069756 | AE23: =IF(OR(O23="",U23=""),"",IF(U23=0,"",(O23-U23)/U23)) | AF23: =IF(OR(P23="",V23=""),"",IF(V23=0,"",(P23-V23)/V23)) | AG23: =IF(OR(Q23="",I23=""),"",IF(I23=0,"",(Q23-I23)/I23)) -> 0.011486001 | AH23: =IF(OR(R23="",W23=""),"",IF(W23=0,"",(R23-W23)/W23)) | AI23: =IF(OR(S23="",Z23=""),"",IF(Z23=0,"",(S23*1000-Z23)/Z23)) | AJ23: =IF(OR(Q23="",T23=""),"",IF(T23=0,"",(Q23-T23)/T23)) -> 0.015349139 | AK23: =IF(OR(R23="",U23=""),"",IF(U23=0,"",(R23-U23)/U23)) | AL23: =IF(OR(S23="",V23=""),"",IF(V23=0,"",(S23*1000-V23)/V23)) | AM23: =IF(OR(I23="",T23=""),"",IF(T23=0,"",(I23-T23)/T23)) -> 0.0038192693 | AN23: =IF(OR(W23="",U23=""),"",IF(U23=0,"",(W23-U23)/U23)) -> -0.20301614 | AO23: =IF(OR(Z23="",V23=""),"",IF(V23=0,"",(Z23-V23)/V23)) | AP23: =IF(OR(N23="",O23="",P23="",Q23="",R23="",S23=""),"",IF(AND(ABS(N23-Q23)<=Setup!$B$20,ABS(O23-R23)<=Setup!$B$21,ABS(P23-S23*1000)<=Setup!$B$22),"OK","CHECK")) | AQ23: =IF(OR(N23="",O23="",P23="",I23="",W23="",Z23=""),"",IF(AND(ABS(N23-I23)/Setup!$B$17<=Setup!$B$16/100,ABS(O23-W23)/Setup!$B$18<=Setup!$B$16/100,ABS(P23-Z23)/Setup!$B$19<=Setup!$B$16/100),"PASS","FAIL")) | AR23: =IF(OR(I23="",N23="",N23=0),"",I23/N23) -> 0.98794326 | AS23: =IF(OR(W23="",O23="",O23=0),"",W23/O23) | AT23: =IF(OR(Z23="",P23="",P23=0),"",Z23/P23)
A24: 18 | T24: =IF(D24="","",D24) | U24: =IF(OR(D24="",G24="",D24=0),"",G24/D24*1000) | V24: =IF(OR(G24="",H24=""),"",G24*H24*1000) | W24: =IF(J24="","",J24/Setup!$B$14) | X24: =IF(OR(L24="",M24=""),"",360*M24*L24/1000000) | Y24: =IF(X24="","",COS(RADIANS(X24))) | Z24: =IF(OR(I24="",W24="",Y24=""),"",I24*W24*Y24) | AA24: =IF(OR(N24="",I24=""),"",IF(I24=0,"",(N24-I24)/I24)) | AB24: =IF(OR(O24="",W24=""),"",IF(W24=0,"",(O24-W24)/W24)) | AC24: =IF(OR(P24="",Z24=""),"",IF(Z24=0,"",(P24-Z24)/Z24)) | AD24: =IF(OR(N24="",T24=""),"",IF(T24=0,"",(N24-T24)/T24)) | AE24: =IF(OR(O24="",U24=""),"",IF(U24=0,"",(O24-U24)/U24)) | AF24: =IF(OR(P24="",V24=""),"",IF(V24=0,"",(P24-V24)/V24)) | AG24: =IF(OR(Q24="",I24=""),"",IF(I24=0,"",(Q24-I24)/I24)) | AH24: =IF(OR(R24="",W24=""),"",IF(W24=0,"",(R24-W24)/W24)) | AI24: =IF(OR(S24="",Z24=""),"",IF(Z24=0,"",(S24*1000-Z24)/Z24)) | AJ24: =IF(OR(Q24="",T24=""),"",IF(T24=0,"",(Q24-T24)/T24)) | AK24: =IF(OR(R24="",U24=""),"",IF(U24=0,"",(R24-U24)/U24)) | AL24: =IF(OR(S24="",V24=""),"",IF(V24=0,"",(S24*1000-V24)/V24)) | AM24: =IF(OR(I24="",T24=""),"",IF(T24=0,"",(I24-T24)/T24)) | AN24: =IF(OR(W24="",U24=""),"",IF(U24=0,"",(W24-U24)/U24)) | AO24: =IF(OR(Z24="",V24=""),"",IF(V24=0,"",(Z24-V24)/V24)) | AP24: =IF(OR(N24="",O24="",P24="",Q24="",R24="",S24=""),"",IF(AND(ABS(N24-Q24)<=Setup!$B$20,ABS(O24-R24)<=Setup!$B$21,ABS(P24-S24*1000)<=Setup!$B$22),"OK","CHECK")) | AQ24: =IF(OR(N24="",O24="",P24="",I24="",W24="",Z24=""),"",IF(AND(ABS(N24-I24)/Setup!$B$17<=Setup!$B$16/100,ABS(O24-W24)/Setup!$B$18<=Setup!$B$16/100,ABS(P24-Z24)/Setup!$B$19<=Setup!$B$16/100),"PASS","FAIL")) | AR24: =IF(OR(I24="",N24="",N24=0),"",I24/N24) | AS24: =IF(OR(W24="",O24="",O24=0),"",W24/O24) | AT24: =IF(OR(Z24="",P24="",P24=0),"",Z24/P24)
A25: 19 | T25: =IF(D25="","",D25) | U25: =IF(OR(D25="",G25="",D25=0),"",G25/D25*1000) | V25: =IF(OR(G25="",H25=""),"",G25*H25*1000) | W25: =IF(J25="","",J25/Setup!$B$14) | X25: =IF(OR(L25="",M25=""),"",360*M25*L25/1000000) | Y25: =IF(X25="","",COS(RADIANS(X25))) | Z25: =IF(OR(I25="",W25="",Y25=""),"",I25*W25*Y25) | AA25: =IF(OR(N25="",I25=""),"",IF(I25=0,"",(N25-I25)/I25)) | AB25: =IF(OR(O25="",W25=""),"",IF(W25=0,"",(O25-W25)/W25)) | AC25: =IF(OR(P25="",Z25=""),"",IF(Z25=0,"",(P25-Z25)/Z25)) | AD25: =IF(OR(N25="",T25=""),"",IF(T25=0,"",(N25-T25)/T25)) | AE25: =IF(OR(O25="",U25=""),"",IF(U25=0,"",(O25-U25)/U25)) | AF25: =IF(OR(P25="",V25=""),"",IF(V25=0,"",(P25-V25)/V25)) | AG25: =IF(OR(Q25="",I25=""),"",IF(I25=0,"",(Q25-I25)/I25)) | AH25: =IF(OR(R25="",W25=""),"",IF(W25=0,"",(R25-W25)/W25)) | AI25: =IF(OR(S25="",Z25=""),"",IF(Z25=0,"",(S25*1000-Z25)/Z25)) | AJ25: =IF(OR(Q25="",T25=""),"",IF(T25=0,"",(Q25-T25)/T25)) | AK25: =IF(OR(R25="",U25=""),"",IF(U25=0,"",(R25-U25)/U25)) | AL25: =IF(OR(S25="",V25=""),"",IF(V25=0,"",(S25*1000-V25)/V25)) | AM25: =IF(OR(I25="",T25=""),"",IF(T25=0,"",(I25-T25)/T25)) | AN25: =IF(OR(W25="",U25=""),"",IF(U25=0,"",(W25-U25)/U25)) | AO25: =IF(OR(Z25="",V25=""),"",IF(V25=0,"",(Z25-V25)/V25)) | AP25: =IF(OR(N25="",O25="",P25="",Q25="",R25="",S25=""),"",IF(AND(ABS(N25-Q25)<=Setup!$B$20,ABS(O25-R25)<=Setup!$B$21,ABS(P25-S25*1000)<=Setup!$B$22),"OK","CHECK")) | AQ25: =IF(OR(N25="",O25="",P25="",I25="",W25="",Z25=""),"",IF(AND(ABS(N25-I25)/Setup!$B$17<=Setup!$B$16/100,ABS(O25-W25)/Setup!$B$18<=Setup!$B$16/100,ABS(P25-Z25)/Setup!$B$19<=Setup!$B$16/100),"PASS","FAIL")) | AR25: =IF(OR(I25="",N25="",N25=0),"",I25/N25) | AS25: =IF(OR(W25="",O25="",O25=0),"",W25/O25) | AT25: =IF(OR(Z25="",P25="",P25=0),"",Z25/P25)
A26: 20 | T26: =IF(D26="","",D26) | U26: =IF(OR(D26="",G26="",D26=0),"",G26/D26*1000) | V26: =IF(OR(G26="",H26=""),"",G26*H26*1000) | W26: =IF(J26="","",J26/Setup!$B$14) | X26: =IF(OR(L26="",M26=""),"",360*M26*L26/1000000) | Y26: =IF(X26="","",COS(RADIANS(X26))) | Z26: =IF(OR(I26="",W26="",Y26=""),"",I26*W26*Y26) | AA26: =IF(OR(N26="",I26=""),"",IF(I26=0,"",(N26-I26)/I26)) | AB26: =IF(OR(O26="",W26=""),"",IF(W26=0,"",(O26-W26)/W26)) | AC26: =IF(OR(P26="",Z26=""),"",IF(Z26=0,"",(P26-Z26)/Z26)) | AD26: =IF(OR(N26="",T26=""),"",IF(T26=0,"",(N26-T26)/T26)) | AE26: =IF(OR(O26="",U26=""),"",IF(U26=0,"",(O26-U26)/U26)) | AF26: =IF(OR(P26="",V26=""),"",IF(V26=0,"",(P26-V26)/V26)) | AG26: =IF(OR(Q26="",I26=""),"",IF(I26=0,"",(Q26-I26)/I26)) | AH26: =IF(OR(R26="",W26=""),"",IF(W26=0,"",(R26-W26)/W26)) | AI26: =IF(OR(S26="",Z26=""),"",IF(Z26=0,"",(S26*1000-Z26)/Z26)) | AJ26: =IF(OR(Q26="",T26=""),"",IF(T26=0,"",(Q26-T26)/T26)) | AK26: =IF(OR(R26="",U26=""),"",IF(U26=0,"",(R26-U26)/U26)) | AL26: =IF(OR(S26="",V26=""),"",IF(V26=0,"",(S26*1000-V26)/V26)) | AM26: =IF(OR(I26="",T26=""),"",IF(T26=0,"",(I26-T26)/T26)) | AN26: =IF(OR(W26="",U26=""),"",IF(U26=0,"",(W26-U26)/U26)) | AO26: =IF(OR(Z26="",V26=""),"",IF(V26=0,"",(Z26-V26)/V26)) | AP26: =IF(OR(N26="",O26="",P26="",Q26="",R26="",S26=""),"",IF(AND(ABS(N26-Q26)<=Setup!$B$20,ABS(O26-R26)<=Setup!$B$21,ABS(P26-S26*1000)<=Setup!$B$22),"OK","CHECK")) | AQ26: =IF(OR(N26="",O26="",P26="",I26="",W26="",Z26=""),"",IF(AND(ABS(N26-I26)/Setup!$B$17<=Setup!$B$16/100,ABS(O26-W26)/Setup!$B$18<=Setup!$B$16/100,ABS(P26-Z26)/Setup!$B$19<=Setup!$B$16/100),"PASS","FAIL")) | AR26: =IF(OR(I26="",N26="",N26=0),"",I26/N26) | AS26: =IF(OR(W26="",O26="",O26=0),"",W26/O26) | AT26: =IF(OR(Z26="",P26="",P26=0),"",Z26/P26)
G27: RL | O27: Ipeak
B28: Load 1 | C28: 20V | D28: 12.76 | E28: 12.55 | F28: 21.5 | G28: =(E28*E28)/(F28*F28) -> 0.34073012 | I28: 12.83 | J28: 249 | K28: 33 | L28: =(0.002)*(K28/360)*1000000 -> 183.33333 | M28: 502 | N28: 12.8 | O28: 494 | P28: 5.49 | Q28: 12.84 | R28: 494 | S28: 5.53 | T28: =IF(D28="","",D28) -> 12.76 | U28: =IF(OR(D28="",G28="",D28=0),"",G28/D28*1000) -> 26.702988 | V28: =IF(OR(G28="",H28=""),"",G28*H28*1000) | W28: =IF(J28="","",J28/Setup!$B$14) -> 498 | X28: =IF(OR(L28="",M28=""),"",360*M28*L28/1000000) -> 33.132 | Y28: =IF(X28="","",COS(RADIANS(X28))) -> 0.83741359 | Z28: =IF(OR(I28="",W28="",Y28=""),"",I28*W28*Y28) -> 5350.5201 | AA28: =IF(OR(N28="",I28=""),"",IF(I28=0,"",(N28-I28)/I28)) -> -0.0023382697 | AB28: =IF(OR(O28="",W28=""),"",IF(W28=0,"",(O28-W28)/W28)) -> -0.0080321285 | AC28: =IF(OR(P28="",Z28=""),"",IF(Z28=0,"",(P28-Z28)/Z28)) -> -0.99897393 | AD28: =IF(OR(N28="",T28=""),"",IF(T28=0,"",(N28-T28)/T28)) -> 0.0031347962 | AE28: =IF(OR(O28="",U28=""),"",IF(U28=0,"",(O28-U28)/U28)) -> 17.499802 | AF28: =IF(OR(P28="",V28=""),"",IF(V28=0,"",(P28-V28)/V28)) | AG28: =IF(OR(Q28="",I28=""),"",IF(I28=0,"",(Q28-I28)/I28)) -> 0.00077942323 | AH28: =IF(OR(R28="",W28=""),"",IF(W28=0,"",(R28-W28)/W28)) -> -0.0080321285 | AI28: =IF(OR(S28="",Z28=""),"",IF(Z28=0,"",(S28*1000-Z28)/Z28)) -> 0.033544381 | AJ28: =IF(OR(Q28="",T28=""),"",IF(T28=0,"",(Q28-T28)/T28)) -> 0.0062695925 | AK28: =IF(OR(R28="",U28=""),"",IF(U28=0,"",(R28-U28)/U28)) -> 17.499802 | AL28: =IF(OR(S28="",V28=""),"",IF(V28=0,"",(S28*1000-V28)/V28)) | AM28: =IF(OR(I28="",T28=""),"",IF(T28=0,"",(I28-T28)/T28)) -> 0.0054858934 | AN28: =IF(OR(W28="",U28=""),"",IF(U28=0,"",(W28-U28)/U28)) -> 17.649598 | AO28: =IF(OR(Z28="",V28=""),"",IF(V28=0,"",(Z28-V28)/V28)) | AP28: =IF(OR(N28="",O28="",P28="",Q28="",R28="",S28=""),"",IF(AND(ABS(N28-Q28)<=Setup!$B$20,ABS(O28-R28)<=Setup!$B$21,ABS(P28-S28*1000)<=Setup!$B$22),"OK","CHECK")) -> CHECK | AQ28: =IF(OR(N28="",O28="",P28="",I28="",W28="",Z28=""),"",IF(AND(ABS(N28-I28)/Setup!$B$17<=Setup!$B$16/100,ABS(O28-W28)/Setup!$B$18<=Setup!$B$16/100,ABS(P28-Z28)/Setup!$B$19<=Setup!$B$16/100),"PASS","FAIL")) -> FAIL | AR28: =IF(OR(I28="",N28="",N28=0),"",I28/N28) -> 1.0023437 | AS28: =IF(OR(W28="",O28="",O28=0),"",W28/O28) -> 1.0080972 | AT28: =IF(OR(Z28="",P28="",P28=0),"",Z28/P28) -> 974.59383
B29: Load 1 | C29: 20V | D29: 12.84 | E29: 12.76 | F29: 60.65 | I29: 12.92 | J29: 101.79 | K29: 14 | L29: =(0.002)*(K29/360)*1000000 -> 77.777778 | M29: 502 | N29: 12.9 | O29: 286 | P29: 2.54 | Q29: 12.92 | R29: 202 | S29: 2.56 | T29: =IF(D29="","",D29) -> 12.84 | U29: =IF(OR(D29="",G29="",D29=0),"",G29/D29*1000) | V29: =IF(OR(G29="",H29=""),"",G29*H29*1000) | W29: =IF(J29="","",J29/Setup!$B$14) -> 203.58 | X29: =IF(OR(L29="",M29=""),"",360*M29*L29/1000000) -> 14.056 | Y29: =IF(X29="","",COS(RADIANS(X29))) -> 0.97005881 | Z29: =IF(OR(I29="",W29="",Y29=""),"",I29*W29*Y29) -> 2551.5007 | AA29: =IF(OR(N29="",I29=""),"",IF(I29=0,"",(N29-I29)/I29)) -> -0.0015479876 | AB29: =IF(OR(O29="",W29=""),"",IF(W29=0,"",(O29-W29)/W29)) -> 0.40485313 | AC29: =IF(OR(P29="",Z29=""),"",IF(Z29=0,"",(P29-Z29)/Z29)) -> -0.99900451 | AD29: =IF(OR(N29="",T29=""),"",IF(T29=0,"",(N29-T29)/T29)) -> 0.0046728972 | AE29: =IF(OR(O29="",U29=""),"",IF(U29=0,"",(O29-U29)/U29)) | AF29: =IF(OR(P29="",V29=""),"",IF(V29=0,"",(P29-V29)/V29)) | AG29: =IF(OR(Q29="",I29=""),"",IF(I29=0,"",(Q29-I29)/I29)) -> 0 | AH29: =IF(OR(R29="",W29=""),"",IF(W29=0,"",(R29-W29)/W29)) -> -0.0077610767 | AI29: =IF(OR(S29="",Z29=""),"",IF(Z29=0,"",(S29*1000-Z29)/Z29)) -> 0.0033311051 | AJ29: =IF(OR(Q29="",T29=""),"",IF(T29=0,"",(Q29-T29)/T29)) -> 0.0062305296 | AK29: =IF(OR(R29="",U29=""),"",IF(U29=0,"",(R29-U29)/U29)) | AL29: =IF(OR(S29="",V29=""),"",IF(V29=0,"",(S29*1000-V29)/V29)) | AM29: =IF(OR(I29="",T29=""),"",IF(T29=0,"",(I29-T29)/T29)) -> 0.0062305296 | AN29: =IF(OR(W29="",U29=""),"",IF(U29=0,"",(W29-U29)/U29)) | AO29: =IF(OR(Z29="",V29=""),"",IF(V29=0,"",(Z29-V29)/V29)) | AP29: =IF(OR(N29="",O29="",P29="",Q29="",R29="",S29=""),"",IF(AND(ABS(N29-Q29)<=Setup!$B$20,ABS(O29-R29)<=Setup!$B$21,ABS(P29-S29*1000)<=Setup!$B$22),"OK","CHECK")) -> CHECK | AQ29: =IF(OR(N29="",O29="",P29="",I29="",W29="",Z29=""),"",IF(AND(ABS(N29-I29)/Setup!$B$17<=Setup!$B$16/100,ABS(O29-W29)/Setup!$B$18<=Setup!$B$16/100,ABS(P29-Z29)/Setup!$B$19<=Setup!$B$16/100),"PASS","FAIL")) -> FAIL | AR29: =IF(OR(I29="",N29="",N29=0),"",I29/N29) -> 1.0015504 | AS29: =IF(OR(W29="",O29="",O29=0),"",W29/O29) -> 0.71181818 | AT29: =IF(OR(Z29="",P29="",P29=0),"",Z29/P29) -> 1004.5278
B30: Load 1 | C30: 20V | D30: 12.9 | E30: 12.84 | F30: 95.24 | I30: 12.97 | J30: 66.28 | K30: 7.11 | L30: =(0.002)*(K30/360)*1000000 -> 39.5 | M30: 502 | N30: 13 | O30: 187 | P30: 1.69 | Q30: 12.96 | R30: 187 | S30: 1.69 | T30: =IF(D30="","",D30) -> 12.9 | U30: =IF(OR(D30="",G30="",D30=0),"",G30/D30*1000) | V30: =IF(OR(G30="",H30=""),"",G30*H30*1000) | W30: =IF(J30="","",J30/Setup!$B$14) -> 132.56 | X30: =IF(OR(L30="",M30=""),"",360*M30*L30/1000000) -> 7.13844 | Y30: =IF(X30="","",COS(RADIANS(X30))) -> 0.99224879 | Z30: =IF(OR(I30="",W30="",Y30=""),"",I30*W30*Y30) -> 1705.9765 | AA30: =IF(OR(N30="",I30=""),"",IF(I30=0,"",(N30-I30)/I30)) -> 0.0023130301 | AB30: =IF(OR(O30="",W30=""),"",IF(W30=0,"",(O30-W30)/W30)) -> 0.41068196 | AC30: =IF(OR(P30="",Z30=""),"",IF(Z30=0,"",(P30-Z30)/Z30)) -> -0.99900937 | AD30: =IF(OR(N30="",T30=""),"",IF(T30=0,"",(N30-T30)/T30)) -> 0.007751938 | AE30: =IF(OR(O30="",U30=""),"",IF(U30=0,"",(O30-U30)/U30)) | AF30: =IF(OR(P30="",V30=""),"",IF(V30=0,"",(P30-V30)/V30)) | AG30: =IF(OR(Q30="",I30=""),"",IF(I30=0,"",(Q30-I30)/I30)) -> -0.00077101002 | AH30: =IF(OR(R30="",W30=""),"",IF(W30=0,"",(R30-W30)/W30)) -> 0.41068196 | AI30: =IF(OR(S30="",Z30=""),"",IF(Z30=0,"",(S30*1000-Z30)/Z30)) -> -0.0093650289 | AJ30: =IF(OR(Q30="",T30=""),"",IF(T30=0,"",(Q30-T30)/T30)) -> 0.0046511628 | AK30: =IF(OR(R30="",U30=""),"",IF(U30=0,"",(R30-U30)/U30)) | AL30: =IF(OR(S30="",V30=""),"",IF(V30=0,"",(S30*1000-V30)/V30)) | AM30: =IF(OR(I30="",T30=""),"",IF(T30=0,"",(I30-T30)/T30)) -> 0.0054263566 | AN30: =IF(OR(W30="",U30=""),"",IF(U30=0,"",(W30-U30)/U30)) | AO30: =IF(OR(Z30="",V30=""),"",IF(V30=0,"",(Z30-V30)/V30)) | AP30: =IF(OR(N30="",O30="",P30="",Q30="",R30="",S30=""),"",IF(AND(ABS(N30-Q30)<=Setup!$B$20,ABS(O30-R30)<=Setup!$B$21,ABS(P30-S30*1000)<=Setup!$B$22),"OK","CHECK")) -> CHECK | AQ30: =IF(OR(N30="",O30="",P30="",I30="",W30="",Z30=""),"",IF(AND(ABS(N30-I30)/Setup!$B$17<=Setup!$B$16/100,ABS(O30-W30)/Setup!$B$18<=Setup!$B$16/100,ABS(P30-Z30)/Setup!$B$19<=Setup!$B$16/100),"PASS","FAIL")) -> FAIL | AR30: =IF(OR(I30="",N30="",N30=0),"",I30/N30) -> 0.99769231 | AS30: =IF(OR(W30="",O30="",O30=0),"",W30/O30) -> 0.70887701 | AT30: =IF(OR(Z30="",P30="",P30=0),"",Z30/P30) -> 1009.4536
B31: Load 2 | C31: 22V | D31: 12.93 | E31: 12.72 | F31: 21.5 | I31: 13.04 | J31: 247.2 | K31: 29 | L31: =(0.002)*(K31/360)*1000000 -> 161.11111 | M31: 501 | N31: 13 | O31: 707 | P31: 5.68 | Q31: 13 | R31: 707 | S31: 5.62 | T31: =IF(D31="","",D31) -> 12.93 | U31: =IF(OR(D31="",G31="",D31=0),"",G31/D31*1000) | V31: =IF(OR(G31="",H31=""),"",G31*H31*1000) | W31: =IF(J31="","",J31/Setup!$B$14) -> 494.4 | X31: =IF(OR(L31="",M31=""),"",360*M31*L31/1000000) -> 29.058 | Y31: =IF(X31="","",COS(RADIANS(X31))) -> 0.87412849 | Z31: =IF(OR(I31="",W31="",Y31=""),"",I31*W31*Y31) -> 5635.4854 | AA31: =IF(OR(N31="",I31=""),"",IF(I31=0,"",(N31-I31)/I31)) -> -0.0030674847 | AB31: =IF(OR(O31="",W31=""),"",IF(W31=0,"",(O31-W31)/W31)) -> 0.43001618 | AC31: =IF(OR(P31="",Z31=""),"",IF(Z31=0,"",(P31-Z31)/Z31)) -> -0.9989921 | AD31: =IF(OR(N31="",T31=""),"",IF(T31=0,"",(N31-T31)/T31)) -> 0.0054137664 | AE31: =IF(OR(O31="",U31=""),"",IF(U31=0,"",(O31-U31)/U31)) | AF31: =IF(OR(P31="",V31=""),"",IF(V31=0,"",(P31-V31)/V31)) | AG31: =IF(OR(Q31="",I31=""),"",IF(I31=0,"",(Q31-I31)/I31)) -> -0.0030674847 | AH31: =IF(OR(R31="",W31=""),"",IF(W31=0,"",(R31-W31)/W31)) -> 0.43001618 | AI31: =IF(OR(S31="",Z31=""),"",IF(Z31=0,"",(S31*1000-Z31)/Z31)) -> -0.0027478379 | AJ31: =IF(OR(Q31="",T31=""),"",IF(T31=0,"",(Q31-T31)/T31)) -> 0.0054137664 | AK31: =IF(OR(R31="",U31=""),"",IF(U31=0,"",(R31-U31)/U31)) | AL31: =IF(OR(S31="",V31=""),"",IF(V31=0,"",(S31*1000-V31)/V31)) | AM31: =IF(OR(I31="",T31=""),"",IF(T31=0,"",(I31-T31)/T31)) -> 0.0085073473 | AN31: =IF(OR(W31="",U31=""),"",IF(U31=0,"",(W31-U31)/U31)) | AO31: =IF(OR(Z31="",V31=""),"",IF(V31=0,"",(Z31-V31)/V31)) | AP31: =IF(OR(N31="",O31="",P31="",Q31="",R31="",S31=""),"",IF(AND(ABS(N31-Q31)<=Setup!$B$20,ABS(O31-R31)<=Setup!$B$21,ABS(P31-S31*1000)<=Setup!$B$22),"OK","CHECK")) -> CHECK | AQ31: =IF(OR(N31="",O31="",P31="",I31="",W31="",Z31=""),"",IF(AND(ABS(N31-I31)/Setup!$B$17<=Setup!$B$16/100,ABS(O31-W31)/Setup!$B$18<=Setup!$B$16/100,ABS(P31-Z31)/Setup!$B$19<=Setup!$B$16/100),"PASS","FAIL")) -> FAIL | AR31: =IF(OR(I31="",N31="",N31=0),"",I31/N31) -> 1.0030769 | AS31: =IF(OR(W31="",O31="",O31=0),"",W31/O31) -> 0.69929279 | AT31: =IF(OR(Z31="",P31="",P31=0),"",Z31/P31) -> 992.16292
B32: Load 2 | C32: 22V | D32: 13.08 | E32: 12.99 | F32: 63.2 | I32: 13.17 | J32: 96.6 | K32: 11.7 | L32: =(0.002)*(K32/360)*1000000 -> 65 | M32: 501 | N32: 13.1 | O32: 275 | P32: 2.48 | Q32: 13.15 | R32: 274 | S32: 2.49 | T32: =IF(D32="","",D32) -> 13.08 | U32: =IF(OR(D32="",G32="",D32=0),"",G32/D32*1000) | V32: =IF(OR(G32="",H32=""),"",G32*H32*1000) | W32: =IF(J32="","",J32/Setup!$B$14) -> 193.2 | X32: =IF(OR(L32="",M32=""),"",360*M32*L32/1000000) -> 11.7234 | Y32: =IF(X32="","",COS(RADIANS(X32))) -> 0.97913991 | Z32: =IF(OR(I32="",W32="",Y32=""),"",I32*W32*Y32) -> 2491.3667 | AA32: =IF(OR(N32="",I32=""),"",IF(I32=0,"",(N32-I32)/I32)) -> -0.0053151101 | AB32: =IF(OR(O32="",W32=""),"",IF(W32=0,"",(O32-W32)/W32)) -> 0.42339545 | AC32: =IF(OR(P32="",Z32=""),"",IF(Z32=0,"",(P32-Z32)/Z32)) -> -0.99900456 | AD32: =IF(OR(N32="",T32=""),"",IF(T32=0,"",(N32-T32)/T32)) -> 0.001529052 | AE32: =IF(OR(O32="",U32=""),"",IF(U32=0,"",(O32-U32)/U32)) | AF32: =IF(OR(P32="",V32=""),"",IF(V32=0,"",(P32-V32)/V32)) | AG32: =IF(OR(Q32="",I32=""),"",IF(I32=0,"",(Q32-I32)/I32)) -> -0.0015186029 | AH32: =IF(OR(R32="",W32=""),"",IF(W32=0,"",(R32-W32)/W32)) -> 0.41821946 | AI32: =IF(OR(S32="",Z32=""),"",IF(Z32=0,"",(S32*1000-Z32)/Z32)) -> -0.00054856121 | AJ32: =IF(OR(Q32="",T32=""),"",IF(T32=0,"",(Q32-T32)/T32)) -> 0.005351682 | AK32: =IF(OR(R32="",U32=""),"",IF(U32=0,"",(R32-U32)/U32)) | AL32: =IF(OR(S32="",V32=""),"",IF(V32=0,"",(S32*1000-V32)/V32)) | AM32: =IF(OR(I32="",T32=""),"",IF(T32=0,"",(I32-T32)/T32)) -> 0.0068807339 | AN32: =IF(OR(W32="",U32=""),"",IF(U32=0,"",(W32-U32)/U32)) | AO32: =IF(OR(Z32="",V32=""),"",IF(V32=0,"",(Z32-V32)/V32)) | AP32: =IF(OR(N32="",O32="",P32="",Q32="",R32="",S32=""),"",IF(AND(ABS(N32-Q32)<=Setup!$B$20,ABS(O32-R32)<=Setup!$B$21,ABS(P32-S32*1000)<=Setup!$B$22),"OK","CHECK")) -> CHECK | AQ32: =IF(OR(N32="",O32="",P32="",I32="",W32="",Z32=""),"",IF(AND(ABS(N32-I32)/Setup!$B$17<=Setup!$B$16/100,ABS(O32-W32)/Setup!$B$18<=Setup!$B$16/100,ABS(P32-Z32)/Setup!$B$19<=Setup!$B$16/100),"PASS","FAIL")) -> FAIL | AR32: =IF(OR(I32="",N32="",N32=0),"",I32/N32) -> 1.0053435 | AS32: =IF(OR(W32="",O32="",O32=0),"",W32/O32) -> 0.70254545 | AT32: =IF(OR(Z32="",P32="",P32=0),"",Z32/P32) -> 1004.5833
B33: Load 2 | C33: 22V | D33: 13.099 | E33: 13.03 | F33: 93.3 | I33: 13.16 | J33: 68.37 | K33: 8.56 | L33: =(0.002)*(K33/360)*1000000 -> 47.555556 | M33: 501 | N33: 13.2 | O33: 194 | P33: 1.77 | Q33: 13.16 | R33: 194 | S33: 1.76 | T33: =IF(D33="","",D33) -> 13.099 | U33: =IF(OR(D33="",G33="",D33=0),"",G33/D33*1000) | V33: =IF(OR(G33="",H33=""),"",G33*H33*1000) | W33: =IF(J33="","",J33/Setup!$B$14) -> 136.74 | X33: =IF(OR(L33="",M33=""),"",360*M33*L33/1000000) -> 8.57712 | Y33: =IF(X33="","",COS(RADIANS(X33))) -> 0.98881602 | Z33: =IF(OR(I33="",W33="",Y33=""),"",I33*W33*Y33) -> 1779.3728 | AA33: =IF(OR(N33="",I33=""),"",IF(I33=0,"",(N33-I33)/I33)) -> 0.0030395137 | AB33: =IF(OR(O33="",W33=""),"",IF(W33=0,"",(O33-W33)/W33)) -> 0.41875091 | AC33: =IF(OR(P33="",Z33=""),"",IF(Z33=0,"",(P33-Z33)/Z33)) -> -0.99900527 | AD33: =IF(OR(N33="",T33=""),"",IF(T33=0,"",(N33-T33)/T33)) -> 0.0077105123 | AE33: =IF(OR(O33="",U33=""),"",IF(U33=0,"",(O33-U33)/U33)) | AF33: =IF(OR(P33="",V33=""),"",IF(V33=0,"",(P33-V33)/V33)) | AG33: =IF(OR(Q33="",I33=""),"",IF(I33=0,"",(Q33-I33)/I33)) -> 0 | AH33: =IF(OR(R33="",W33=""),"",IF(W33=0,"",(R33-W33)/W33)) -> 0.41875091 | AI33: =IF(OR(S33="",Z33=""),"",IF(Z33=0,"",(S33*1000-Z33)/Z33)) -> -0.010887454 | AJ33: =IF(OR(Q33="",T33=""),"",IF(T33=0,"",(Q33-T33)/T33)) -> 0.004656844 | AK33: =IF(OR(R33="",U33=""),"",IF(U33=0,"",(R33-U33)/U33)) | AL33: =IF(OR(S33="",V33=""),"",IF(V33=0,"",(S33*1000-V33)/V33)) | AM33: =IF(OR(I33="",T33=""),"",IF(T33=0,"",(I33-T33)/T33)) -> 0.004656844 | AN33: =IF(OR(W33="",U33=""),"",IF(U33=0,"",(W33-U33)/U33)) | AO33: =IF(OR(Z33="",V33=""),"",IF(V33=0,"",(Z33-V33)/V33)) | AP33: =IF(OR(N33="",O33="",P33="",Q33="",R33="",S33=""),"",IF(AND(ABS(N33-Q33)<=Setup!$B$20,ABS(O33-R33)<=Setup!$B$21,ABS(P33-S33*1000)<=Setup!$B$22),"OK","CHECK")) -> CHECK | AQ33: =IF(OR(N33="",O33="",P33="",I33="",W33="",Z33=""),"",IF(AND(ABS(N33-I33)/Setup!$B$17<=Setup!$B$16/100,ABS(O33-W33)/Setup!$B$18<=Setup!$B$16/100,ABS(P33-Z33)/Setup!$B$19<=Setup!$B$16/100),"PASS","FAIL")) -> FAIL | AR33: =IF(OR(I33="",N33="",N33=0),"",I33/N33) -> 0.9969697 | AS33: =IF(OR(W33="",O33="",O33=0),"",W33/O33) -> 0.70484536 | AT33: =IF(OR(Z33="",P33="",P33=0),"",Z33/P33) -> 1005.2954
B34: Load 3 | C34: 20V | D34: 13.25 | E34: 13.023 | F34: 22.26 | J34: 255 | L34: =(0.002)*(K34/360)*1000000 -> 0 | N34: 13.3 | O34: 728 | P34: 6.02 | Q34: 13.31 | R34: 727 | S34: 6.01 | T34: =IF(D34="","",D34) -> 13.25 | U34: =IF(OR(D34="",G34="",D34=0),"",G34/D34*1000) | V34: =IF(OR(G34="",H34=""),"",G34*H34*1000) | W34: =IF(J34="","",J34/Setup!$B$14) -> 510 | X34: =IF(OR(L34="",M34=""),"",360*M34*L34/1000000) | Y34: =IF(X34="","",COS(RADIANS(X34))) | Z34: =IF(OR(I34="",W34="",Y34=""),"",I34*W34*Y34) | AA34: =IF(OR(N34="",I34=""),"",IF(I34=0,"",(N34-I34)/I34)) | AB34: =IF(OR(O34="",W34=""),"",IF(W34=0,"",(O34-W34)/W34)) -> 0.42745098 | AC34: =IF(OR(P34="",Z34=""),"",IF(Z34=0,"",(P34-Z34)/Z34)) | AD34: =IF(OR(N34="",T34=""),"",IF(T34=0,"",(N34-T34)/T34)) -> 0.0037735849 | AE34: =IF(OR(O34="",U34=""),"",IF(U34=0,"",(O34-U34)/U34)) | AF34: =IF(OR(P34="",V34=""),"",IF(V34=0,"",(P34-V34)/V34)) | AG34: =IF(OR(Q34="",I34=""),"",IF(I34=0,"",(Q34-I34)/I34)) | AH34: =IF(OR(R34="",W34=""),"",IF(W34=0,"",(R34-W34)/W34)) -> 0.4254902 | AI34: =IF(OR(S34="",Z34=""),"",IF(Z34=0,"",(S34*1000-Z34)/Z34)) | AJ34: =IF(OR(Q34="",T34=""),"",IF(T34=0,"",(Q34-T34)/T34)) -> 0.0045283019 | AK34: =IF(OR(R34="",U34=""),"",IF(U34=0,"",(R34-U34)/U34)) | AL34: =IF(OR(S34="",V34=""),"",IF(V34=0,"",(S34*1000-V34)/V34)) | AM34: =IF(OR(I34="",T34=""),"",IF(T34=0,"",(I34-T34)/T34)) | AN34: =IF(OR(W34="",U34=""),"",IF(U34=0,"",(W34-U34)/U34)) | AO34: =IF(OR(Z34="",V34=""),"",IF(V34=0,"",(Z34-V34)/V34)) | AP34: =IF(OR(N34="",O34="",P34="",Q34="",R34="",S34=""),"",IF(AND(ABS(N34-Q34)<=Setup!$B$20,ABS(O34-R34)<=Setup!$B$21,ABS(P34-S34*1000)<=Setup!$B$22),"OK","CHECK")) -> CHECK | AQ34: =IF(OR(N34="",O34="",P34="",I34="",W34="",Z34=""),"",IF(AND(ABS(N34-I34)/Setup!$B$17<=Setup!$B$16/100,ABS(O34-W34)/Setup!$B$18<=Setup!$B$16/100,ABS(P34-Z34)/Setup!$B$19<=Setup!$B$16/100),"PASS","FAIL")) | AR34: =IF(OR(I34="",N34="",N34=0),"",I34/N34) | AS34: =IF(OR(W34="",O34="",O34=0),"",W34/O34) -> 0.70054945 | AT34: =IF(OR(Z34="",P34="",P34=0),"",Z34/P34)
B35: Load 3 | C35: 26V | L35: =(0.002)*(K35/360)*1000000 -> 0 | T35: =IF(D35="","",D35) | U35: =IF(OR(D35="",G35="",D35=0),"",G35/D35*1000) | V35: =IF(OR(G35="",H35=""),"",G35*H35*1000) | W35: =IF(J35="","",J35/Setup!$B$14) | X35: =IF(OR(L35="",M35=""),"",360*M35*L35/1000000) | Y35: =IF(X35="","",COS(RADIANS(X35))) | Z35: =IF(OR(I35="",W35="",Y35=""),"",I35*W35*Y35) | AA35: =IF(OR(N35="",I35=""),"",IF(I35=0,"",(N35-I35)/I35)) | AB35: =IF(OR(O35="",W35=""),"",IF(W35=0,"",(O35-W35)/W35)) | AC35: =IF(OR(P35="",Z35=""),"",IF(Z35=0,"",(P35-Z35)/Z35)) | AD35: =IF(OR(N35="",T35=""),"",IF(T35=0,"",(N35-T35)/T35)) | AE35: =IF(OR(O35="",U35=""),"",IF(U35=0,"",(O35-U35)/U35)) | AF35: =IF(OR(P35="",V35=""),"",IF(V35=0,"",(P35-V35)/V35)) | AG35: =IF(OR(Q35="",I35=""),"",IF(I35=0,"",(Q35-I35)/I35)) | AH35: =IF(OR(R35="",W35=""),"",IF(W35=0,"",(R35-W35)/W35)) | AI35: =IF(OR(S35="",Z35=""),"",IF(Z35=0,"",(S35*1000-Z35)/Z35)) | AJ35: =IF(OR(Q35="",T35=""),"",IF(T35=0,"",(Q35-T35)/T35)) | AK35: =IF(OR(R35="",U35=""),"",IF(U35=0,"",(R35-U35)/U35)) | AL35: =IF(OR(S35="",V35=""),"",IF(V35=0,"",(S35*1000-V35)/V35)) | AM35: =IF(OR(I35="",T35=""),"",IF(T35=0,"",(I35-T35)/T35)) | AN35: =IF(OR(W35="",U35=""),"",IF(U35=0,"",(W35-U35)/U35)) | AO35: =IF(OR(Z35="",V35=""),"",IF(V35=0,"",(Z35-V35)/V35)) | AP35: =IF(OR(N35="",O35="",P35="",Q35="",R35="",S35=""),"",IF(AND(ABS(N35-Q35)<=Setup!$B$20,ABS(O35-R35)<=Setup!$B$21,ABS(P35-S35*1000)<=Setup!$B$22),"OK","CHECK")) | AQ35: =IF(OR(N35="",O35="",P35="",I35="",W35="",Z35=""),"",IF(AND(ABS(N35-I35)/Setup!$B$17<=Setup!$B$16/100,ABS(O35-W35)/Setup!$B$18<=Setup!$B$16/100,ABS(P35-Z35)/Setup!$B$19<=Setup!$B$16/100),"PASS","FAIL")) | AR35: =IF(OR(I35="",N35="",N35=0),"",I35/N35) | AS35: =IF(OR(W35="",O35="",O35=0),"",W35/O35) | AT35: =IF(OR(Z35="",P35="",P35=0),"",Z35/P35)
B36: Load 3 | C36: 32V | L36: =(0.002)*(K36/360)*1000000 -> 0 | T36: =IF(D36="","",D36) | U36: =IF(OR(D36="",G36="",D36=0),"",G36/D36*1000) | V36: =IF(OR(G36="",H36=""),"",G36*H36*1000) | W36: =IF(J36="","",J36/Setup!$B$14) | X36: =IF(OR(L36="",M36=""),"",360*M36*L36/1000000) | Y36: =IF(X36="","",COS(RADIANS(X36))) | Z36: =IF(OR(I36="",W36="",Y36=""),"",I36*W36*Y36) | AA36: =IF(OR(N36="",I36=""),"",IF(I36=0,"",(N36-I36)/I36)) | AB36: =IF(OR(O36="",W36=""),"",IF(W36=0,"",(O36-W36)/W36)) | AC36: =IF(OR(P36="",Z36=""),"",IF(Z36=0,"",(P36-Z36)/Z36)) | AD36: =IF(OR(N36="",T36=""),"",IF(T36=0,"",(N36-T36)/T36)) | AE36: =IF(OR(O36="",U36=""),"",IF(U36=0,"",(O36-U36)/U36)) | AF36: =IF(OR(P36="",V36=""),"",IF(V36=0,"",(P36-V36)/V36)) | AG36: =IF(OR(Q36="",I36=""),"",IF(I36=0,"",(Q36-I36)/I36)) | AH36: =IF(OR(R36="",W36=""),"",IF(W36=0,"",(R36-W36)/W36)) | AI36: =IF(OR(S36="",Z36=""),"",IF(Z36=0,"",(S36*1000-Z36)/Z36)) | AJ36: =IF(OR(Q36="",T36=""),"",IF(T36=0,"",(Q36-T36)/T36)) | AK36: =IF(OR(R36="",U36=""),"",IF(U36=0,"",(R36-U36)/U36)) | AL36: =IF(OR(S36="",V36=""),"",IF(V36=0,"",(S36*1000-V36)/V36)) | AM36: =IF(OR(I36="",T36=""),"",IF(T36=0,"",(I36-T36)/T36)) | AN36: =IF(OR(W36="",U36=""),"",IF(U36=0,"",(W36-U36)/U36)) | AO36: =IF(OR(Z36="",V36=""),"",IF(V36=0,"",(Z36-V36)/V36)) | AP36: =IF(OR(N36="",O36="",P36="",Q36="",R36="",S36=""),"",IF(AND(ABS(N36-Q36)<=Setup!$B$20,ABS(O36-R36)<=Setup!$B$21,ABS(P36-S36*1000)<=Setup!$B$22),"OK","CHECK")) | AQ36: =IF(OR(N36="",O36="",P36="",I36="",W36="",Z36=""),"",IF(AND(ABS(N36-I36)/Setup!$B$17<=Setup!$B$16/100,ABS(O36-W36)/Setup!$B$18<=Setup!$B$16/100,ABS(P36-Z36)/Setup!$B$19<=Setup!$B$16/100),"PASS","FAIL")) | AR36: =IF(OR(I36="",N36="",N36=0),"",I36/N36) | AS36: =IF(OR(W36="",O36="",O36=0),"",W36/O36) | AT36: =IF(OR(Z36="",P36="",P36=0),"",Z36/P36)
B37: Load 4 | C37: 20V | L37: =(0.002)*(K37/360)*1000000 -> 0 | T37: =IF(D37="","",D37) | U37: =IF(OR(D37="",G37="",D37=0),"",G37/D37*1000) | V37: =IF(OR(G37="",H37=""),"",G37*H37*1000) | W37: =IF(J37="","",J37/Setup!$B$14) | X37: =IF(OR(L37="",M37=""),"",360*M37*L37/1000000) | Y37: =IF(X37="","",COS(RADIANS(X37))) | Z37: =IF(OR(I37="",W37="",Y37=""),"",I37*W37*Y37) | AA37: =IF(OR(N37="",I37=""),"",IF(I37=0,"",(N37-I37)/I37)) | AB37: =IF(OR(O37="",W37=""),"",IF(W37=0,"",(O37-W37)/W37)) | AC37: =IF(OR(P37="",Z37=""),"",IF(Z37=0,"",(P37-Z37)/Z37)) | AD37: =IF(OR(N37="",T37=""),"",IF(T37=0,"",(N37-T37)/T37)) | AE37: =IF(OR(O37="",U37=""),"",IF(U37=0,"",(O37-U37)/U37)) | AF37: =IF(OR(P37="",V37=""),"",IF(V37=0,"",(P37-V37)/V37)) | AG37: =IF(OR(Q37="",I37=""),"",IF(I37=0,"",(Q37-I37)/I37)) | AH37: =IF(OR(R37="",W37=""),"",IF(W37=0,"",(R37-W37)/W37)) | AI37: =IF(OR(S37="",Z37=""),"",IF(Z37=0,"",(S37*1000-Z37)/Z37)) | AJ37: =IF(OR(Q37="",T37=""),"",IF(T37=0,"",(Q37-T37)/T37)) | AK37: =IF(OR(R37="",U37=""),"",IF(U37=0,"",(R37-U37)/U37)) | AL37: =IF(OR(S37="",V37=""),"",IF(V37=0,"",(S37*1000-V37)/V37)) | AM37: =IF(OR(I37="",T37=""),"",IF(T37=0,"",(I37-T37)/T37)) | AN37: =IF(OR(W37="",U37=""),"",IF(U37=0,"",(W37-U37)/U37)) | AO37: =IF(OR(Z37="",V37=""),"",IF(V37=0,"",(Z37-V37)/V37)) | AP37: =IF(OR(N37="",O37="",P37="",Q37="",R37="",S37=""),"",IF(AND(ABS(N37-Q37)<=Setup!$B$20,ABS(O37-R37)<=Setup!$B$21,ABS(P37-S37*1000)<=Setup!$B$22),"OK","CHECK")) | AQ37: =IF(OR(N37="",O37="",P37="",I37="",W37="",Z37=""),"",IF(AND(ABS(N37-I37)/Setup!$B$17<=Setup!$B$16/100,ABS(O37-W37)/Setup!$B$18<=Setup!$B$16/100,ABS(P37-Z37)/Setup!$B$19<=Setup!$B$16/100),"PASS","FAIL")) | AR37: =IF(OR(I37="",N37="",N37=0),"",I37/N37) | AS37: =IF(OR(W37="",O37="",O37=0),"",W37/O37) | AT37: =IF(OR(Z37="",P37="",P37=0),"",Z37/P37)
B38: Load 4 | C38: 26V | L38: =(0.002)*(K38/360)*1000000 -> 0 | T38: =IF(D38="","",D38) | U38: =IF(OR(D38="",G38="",D38=0),"",G38/D38*1000) | V38: =IF(OR(G38="",H38=""),"",G38*H38*1000) | W38: =IF(J38="","",J38/Setup!$B$14) | X38: =IF(OR(L38="",M38=""),"",360*M38*L38/1000000) | Y38: =IF(X38="","",COS(RADIANS(X38))) | Z38: =IF(OR(I38="",W38="",Y38=""),"",I38*W38*Y38) | AA38: =IF(OR(N38="",I38=""),"",IF(I38=0,"",(N38-I38)/I38)) | AB38: =IF(OR(O38="",W38=""),"",IF(W38=0,"",(O38-W38)/W38)) | AC38: =IF(OR(P38="",Z38=""),"",IF(Z38=0,"",(P38-Z38)/Z38)) | AD38: =IF(OR(N38="",T38=""),"",IF(T38=0,"",(N38-T38)/T38)) | AE38: =IF(OR(O38="",U38=""),"",IF(U38=0,"",(O38-U38)/U38)) | AF38: =IF(OR(P38="",V38=""),"",IF(V38=0,"",(P38-V38)/V38)) | AG38: =IF(OR(Q38="",I38=""),"",IF(I38=0,"",(Q38-I38)/I38)) | AH38: =IF(OR(R38="",W38=""),"",IF(W38=0,"",(R38-W38)/W38)) | AI38: =IF(OR(S38="",Z38=""),"",IF(Z38=0,"",(S38*1000-Z38)/Z38)) | AJ38: =IF(OR(Q38="",T38=""),"",IF(T38=0,"",(Q38-T38)/T38)) | AK38: =IF(OR(R38="",U38=""),"",IF(U38=0,"",(R38-U38)/U38)) | AL38: =IF(OR(S38="",V38=""),"",IF(V38=0,"",(S38*1000-V38)/V38)) | AM38: =IF(OR(I38="",T38=""),"",IF(T38=0,"",(I38-T38)/T38)) | AN38: =IF(OR(W38="",U38=""),"",IF(U38=0,"",(W38-U38)/U38)) | AO38: =IF(OR(Z38="",V38=""),"",IF(V38=0,"",(Z38-V38)/V38)) | AP38: =IF(OR(N38="",O38="",P38="",Q38="",R38="",S38=""),"",IF(AND(ABS(N38-Q38)<=Setup!$B$20,ABS(O38-R38)<=Setup!$B$21,ABS(P38-S38*1000)<=Setup!$B$22),"OK","CHECK")) | AQ38: =IF(OR(N38="",O38="",P38="",I38="",W38="",Z38=""),"",IF(AND(ABS(N38-I38)/Setup!$B$17<=Setup!$B$16/100,ABS(O38-W38)/Setup!$B$18<=Setup!$B$16/100,ABS(P38-Z38)/Setup!$B$19<=Setup!$B$16/100),"PASS","FAIL")) | AR38: =IF(OR(I38="",N38="",N38=0),"",I38/N38) | AS38: =IF(OR(W38="",O38="",O38=0),"",W38/O38) | AT38: =IF(OR(Z38="",P38="",P38=0),"",Z38/P38)
